Workbook
Name Slicer_Month: #N/A

Sheet Dashboard
D2: School Management System
A61: =COUNTA(Teachers!A2:A100)-2 -> 12
A62: =COUNTA('Class 6'!A3:A32)+COUNTA('Class 7'!A3:A32)+COUNTA('Class 8'!A3:A32)+COUNTA('Class 9'!A3:A32)+COUNTA('Class 10'!A3:A32) -> 150

Sheet Teachers
A31: Our Faculty
A32: Teacher ID | B32: Name | C32: Subject
A33: 1 | B33: Ananya Sharma | C33: Math
A34: 2 | B34: Rohan Verma | C34: Science
A35: 3 | B35: Vikram Joshi | C35: History
A36: 4 | B36: Arjun Mehta | C36: English
A37: 5 | B37: Neha Gupta | C37: Business Studies
A38: 6 | B38: Karan Patel | C38: Economics
A39: 7 | B39: Nitika | C39: Geography
A40: 8 | B40: Rahul Nair | C40: Music
A41: 9 | B41: Priya Kapoor | C41: Computer Science
A42: 10 | B42: Sakshi Singh | C42: Art
A43: 11 | B43: Jivani | C43: Chemistry
A44: 12 | B44: Yesh | C44: Physics

Sheet Class 6
A1: 🎓 Class 6th Students
A2: Student ID | B2: Name | C2: Math | D2: Science | E2: History | F2: English | G2: Business Studies | H2: Economics | I2: Geography | J2: Music | K2: Computer Science | L2: Art | M2: Chemistry | N2: Physics | O2: Total | P2: Percentage
A3: 1 | B3: Aarav Kumar | C3: 86 | D3: 94 | E3: 82 | F3: 72 | G3: 71 | H3: 69 | I3: 89 | J3: 93 | K3: 80 | L3: 91 | M3: 66 | N3: 69 | O3: =SUM(Table3[[#This Row],[Math]:[Physics]]) -> 962 | P3: =SUM(C3:N3)/1200 -> 0.80166667
A4: 2 | B4: Vihaan Verma | C4: 80 | D4: 69 | E4: 72 | F4: 90 | G4: 67 | H4: 95 | I4: 86 | J4: 90 | K4: 81 | L4: 90 | M4: 71 | N4: 85 | O4: =SUM(Table3[[#This Row],[Math]:[Physics]]) -> 976 | P4: =SUM(C4:N4)/1200 -> 0.81333333
A5: 3 | B5: Ananya Mehta | C5: 78 | D5: 76 | E5: 79 | F5: 87 | G5: 74 | H5: 83 | I5: 80 | J5: 78 | K5: 66 | L5: 70 | M5: 90 | N5: 93 | O5: =SUM(Table3[[#This Row],[Math]:[Physics]]) -> 954 | P5: =SUM(C5:N5)/1200 -> 0.795
A6: 4 | B6: Ishaan Gupta | C6: 84 | D6: 83 | E6: 66 | F6: 69 | G6: 67 | H6: 79 | I6: 78 | J6: 78 | K6: 95 | L6: 71 | M6: 79 | N6: 93 | O6: =SUM(Table3[[#This Row],[Math]:[Physics]]) -> 942 | P6: =SUM(C6:N6)/1200 -> 0.785
A7: 5 | B7: Diya Yadav | C7: 87 | D7: 82 | E7: 84 | F7: 79 | G7: 76 | H7: 65 | I7: 68 | J7: 69 | K7: 89 | L7: 76 | M7: 80 | N7: 71 | O7: =SUM(Table3[[#This Row],[Math]:[Physics]]) -> 926 | P7: =SUM(C7:N7)/1200 -> 0.77166667
A8: 6 | B8: Aditya Patel | C8: 71 | D8: 82 | E8: 83 | F8: 65 | G8: 79 | H8: 89 | I8: 66 | J8: 80 | K8: 72 | L8: 93 | M8: 67 | N8: 94 | O8: =SUM(Table3[[#This Row],[Math]:[Physics]]) -> 941 | P8: =SUM(C8:N8)/1200 -> 0.78416667
A9: 7 | B9: Kavya Singh | C9: 93 | D9: 80 | E9: 69 | F9: 68 | G9: 73 | H9: 76 | I9: 74 | J9: 71 | K9: 69 | L9: 70 | M9: 90 | N9: 70 | O9: =SUM(Table3[[#This Row],[Math]:[Physics]]) -> 903 | P9: =SUM(C9:N9)/1200 -> 0.7525
A10: 8 | B10: Rohan Joshi | C10: 83 | D10: 74 | E10: 68 | F10: 68 | G10: 72 | H10: 79 | I10: 70 | J10: 73 | K10: 83 | L10: 93 | M10: 92 | N10: 78 | O10: =SUM(Table3[[#This Row],[Math]:[Physics]]) -> 933 | P10: =SUM(C10:N10)/1200 -> 0.7775
A11: 9 | B11: Pooja Patel | C11: 88 | D11: 90 | E11: 78 | F11: 88 | G11: 94 | H11: 70 | I11: 95 | J11: 66 | K11: 86 | L11: 77 | M11: 85 | N11: 69 | O11: =SUM(Table3[[#This Row],[Math]:[Physics]]) -> 986 | P11: =SUM(C11:N11)/1200 -> 0.82166667
A12: 10 | B12: Arjun Verma | C12: 90 | D12: 75 | E12: 91 | F12: 69 | G12: 78 | H12: 67 | I12: 76 | J12: 92 | K12: 92 | L12: 80 | M12: 76 | N12: 74 | O12: =SUM(Table3[[#This Row],[Math]:[Physics]]) -> 960 | P12: =SUM(C12:N12)/1200 -> 0.8
A13: 11 | B13: Sneha Joshi | C13: 85 | D13: 78 | E13: 68 | F13: 94 | G13: 87 | H13: 77 | I13: 84 | J13: 89 | K13: 70 | L13: 91 | M13: 69 | N13: 89 | O13: =SUM(Table3[[#This Row],[Math]:[Physics]]) -> 981 | P13: =SUM(C13:N13)/1200 -> 0.8175
A14: 12 | B14: Karan Gupta | C14: 90 | D14: 92 | E14: 89 | F14: 72 | G14: 68 | H14: 94 | I14: 86 | J14: 76 | K14: 69 | L14: 94 | M14: 67 | N14: 72 | O14: =SUM(Table3[[#This Row],[Math]:[Physics]]) -> 969 | P14: =SUM(C14:N14)/1200 -> 0.8075
... A32: 30 | B32: Manish Gupta | C32: 85 | D32: 89 | E32: 82 | F32: 71 | G32: 72 | H32: 75 | I32: 93 | J32: 95 | K32: 72 | L32: 95 | M32: 74 | N32: 80 | O32: =SUM(Table3[[#This Row],[Math]:[Physics]]) -> 983 | P32: =SUM(C32:N32)/1200 -> 0.81916667

Sheet Class 7
A1: 🎓 Class 7th Students
A2: Student ID | B2: Name | C2: Math | D2: Science | E2: History | F2: English | G2: Business Studies | H2: Economics | I2: Geography | J2: Music | K2: Computer Science | L2: Art | M2: Chemistry | N2: Physics | O2: Total | P2: Percentage
A3: 1 | B3: Aarav Joshi | C3: 91 | D3: 69 | E3: 88 | F3: 69 | G3: 90 | H3: 95 | I3: 67 | J3: 67 | K3: 80 | L3: 82 | M3: 93 | N3: 65 | O3: =SUM(Table5[[#This Row],[Math]:[Physics]]) -> 956 | P3: =SUM(C3:N3)/1200 -> 0.79666667
A4: 2 | B4: Vihaan Singh | C4: 77 | D4: 73 | E4: 70 | F4: 89 | G4: 83 | H4: 90 | I4: 86 | J4: 71 | K4: 78 | L4: 68 | M4: 71 | N4: 83 | O4: =SUM(Table5[[#This Row],[Math]:[Physics]]) -> 939 | P4: =SUM(C4:N4)/1200 -> 0.7825
A5: 3 | B5: Ananya Gupta | C5: 78 | D5: 79 | E5: 69 | F5: 73 | G5: 69 | H5: 90 | I5: 76 | J5: 75 | K5: 85 | L5: 74 | M5: 69 | N5: 75 | O5: =SUM(Table5[[#This Row],[Math]:[Physics]]) -> 912 | P5: =SUM(C5:N5)/1200 -> 0.76
A6: 4 | B6: Ishaan Kumar | C6: 92 | D6: 90 | E6: 82 | F6: 94 | G6: 86 | H6: 76 | I6: 67 | J6: 79 | K6: 90 | L6: 72 | M6: 79 | N6: 91 | O6: =SUM(Table5[[#This Row],[Math]:[Physics]]) -> 998 | P6: =SUM(C6:N6)/1200 -> 0.83166667
A7: 5 | B7: Diya Mehta | C7: 73 | D7: 70 | E7: 88 | F7: 76 | G7: 82 | H7: 81 | I7: 93 | J7: 94 | K7: 80 | L7: 91 | M7: 75 | N7: 66 | O7: =SUM(Table5[[#This Row],[Math]:[Physics]]) -> 969 | P7: =SUM(C7:N7)/1200 -> 0.8075
A8: 6 | B8: Aditya Kumar | C8: 92 | D8: 88 | E8: 82 | F8: 76 | G8: 94 | H8: 87 | I8: 91 | J8: 94 | K8: 76 | L8: 72 | M8: 73 | N8: 88 | O8: =SUM(Table5[[#This Row],[Math]:[Physics]]) -> 1013 | P8: =SUM(C8:N8)/1200 -> 0.84416667
A9: 7 | B9: Kavya Verma | C9: 83 | D9: 75 | E9: 83 | F9: 68 | G9: 75 | H9: 80 | I9: 92 | J9: 68 | K9: 84 | L9: 92 | M9: 65 | N9: 68 | O9: =SUM(Table5[[#This Row],[Math]:[Physics]]) -> 933 | P9: =SUM(C9:N9)/1200 -> 0.7775
A10: 8 | B10: Rohan Kumar | C10: 72 | D10: 94 | E10: 65 | F10: 78 | G10: 78 | H10: 90 | I10: 68 | J10: 74 | K10: 74 | L10: 84 | M10: 91 | N10: 77 | O10: =SUM(Table5[[#This Row],[Math]:[Physics]]) -> 945 | P10: =SUM(C10:N10)/1200 -> 0.7875
A11: 9 | B11: Ravi Gupta | C11: 66 | D11: 81 | E11: 90 | F11: 94 | G11: 87 | H11: 94 | I11: 86 | J11: 90 | K11: 85 | L11: 79 | M11: 84 | N11: 86 | O11: =SUM(Table5[[#This Row],[Math]:[Physics]]) -> 1022 | P11: =SUM(C11:N11)/1200 -> 0.85166667
A12: 10 | B12: Arjun Singh | C12: 88 | D12: 67 | E12: 71 | F12: 75 | G12: 74 | H12: 73 | I12: 65 | J12: 66 | K12: 71 | L12: 72 | M12: 82 | N12: 68 | O12: =SUM(Table5[[#This Row],[Math]:[Physics]]) -> 872 | P12: =SUM(C12:N12)/1200 -> 0.72666667
A13: 11 | B13: Sneha Patel | C13: 88 | D13: 65 | E13: 83 | F13: 87 | G13: 90 | H13: 65 | I13: 89 | J13: 77 | K13: 69 | L13: 72 | M13: 84 | N13: 70 | O13: =SUM(Table5[[#This Row],[Math]:[Physics]]) -> 939 | P13: =SUM(C13:N13)/1200 -> 0.7825
A14: 12 | B14: Karan Yadav | C14: 82 | D14: 92 | E14: 73 | F14: 85 | G14: 88 | H14: 80 | I14: 74 | J14: 77 | K14: 94 | L14: 71 | M14: 73 | N14: 95 | O14: =SUM(Table5[[#This Row],[Math]:[Physics]]) -> 984 | P14: =SUM(C14:N14)/1200 -> 0.82
... A32: 30 | B32: Manish Verma | C32: 77 | D32: 93 | E32: 76 | F32: 72 | G32: 65 | H32: 94 | I32: 66 | J32: 65 | K32: 66 | L32: 71 | M32: 89 | N32: 88 | O32: =SUM(Table5[[#This Row],[Math]:[Physics]]) -> 922 | P32: =SUM(C32:N32)/1200 -> 0.76833333

Sheet Class 8
A1: 🎓 Class 8th Students
A2: Student ID | B2: Name | C2: Math | D2: Science | E2: History | F2: English | G2: Business Studies | H2: Economics | I2: Geography | J2: Music | K2: Computer Science | L2: Art | M2: Chemistry | N2: Physics | O2: Total | P2: Percentage
A3: 1 | B3: Aarav Yadav | C3: 82 | D3: 74 | E3: 94 | F3: 93 | G3: 81 | H3: 70 | I3: 74 | J3: 95 | K3: 71 | L3: 82 | M3: 69 | N3: 84 | O3: =SUM(Table6[[#This Row],[Math]:[Physics]]) -> 969 | P3: =SUM(C3:N3)/1200 -> 0.8075
A4: 2 | B4: Vihaan Verma | C4: 94 | D4: 75 | E4: 87 | F4: 65 | G4: 89 | H4: 72 | I4: 67 | J4: 88 | K4: 93 | L4: 72 | M4: 80 | N4: 67 | O4: =SUM(Table6[[#This Row],[Math]:[Physics]]) -> 949 | P4: =SUM(C4:N4)/1200 -> 0.79083333
A5: 3 | B5: Ananya Sharma | C5: 74 | D5: 85 | E5: 77 | F5: 91 | G5: 85 | H5: 71 | I5: 81 | J5: 91 | K5: 73 | L5: 85 | M5: 88 | N5: 70 | O5: =SUM(Table6[[#This Row],[Math]:[Physics]]) -> 971 | P5: =SUM(C5:N5)/1200 -> 0.80916667
A6: 4 | B6: Ishaan Singh | C6: 82 | D6: 70 | E6: 87 | F6: 80 | G6: 89 | H6: 86 | I6: 79 | J6: 81 | K6: 66 | L6: 90 | M6: 72 | N6: 90 | O6: =SUM(Table6[[#This Row],[Math]:[Physics]]) -> 972 | P6: =SUM(C6:N6)/1200 -> 0.81
A7: 5 | B7: Diya Sharma | C7: 69 | D7: 74 | E7: 73 | F7: 75 | G7: 82 | H7: 88 | I7: 77 | J7: 86 | K7: 76 | L7: 72 | M7: 86 | N7: 76 | O7: =SUM(Table6[[#This Row],[Math]:[Physics]]) -> 934 | P7: =SUM(C7:N7)/1200 -> 0.77833333
A8: 6 | B8: Aditya Singh | C8: 69 | D8: 68 | E8: 74 | F8: 90 | G8: 95 | H8: 93 | I8: 74 | J8: 86 | K8: 92 | L8: 89 | M8: 85 | N8: 86 | O8: =SUM(Table6[[#This Row],[Math]:[Physics]]) -> 1001 | P8: =SUM(C8:N8)/1200 -> 0.83416667
A9: 7 | B9: Kavya Sharma | C9: 89 | D9: 69 | E9: 84 | F9: 68 | G9: 75 | H9: 93 | I9: 81 | J9: 79 | K9: 90 | L9: 71 | M9: 69 | N9: 95 | O9: =SUM(Table6[[#This Row],[Math]:[Physics]]) -> 963 | P9: =SUM(C9:N9)/1200 -> 0.8025
A10: 8 | B10: Rohan Kumar | C10: 66 | D10: 81 | E10: 70 | F10: 73 | G10: 71 | H10: 76 | I10: 81 | J10: 82 | K10: 87 | L10: 95 | M10: 93 | N10: 72 | O10: =SUM(Table6[[#This Row],[Math]:[Physics]]) -> 947 | P10: =SUM(C10:N10)/1200 -> 0.78916667
A11: 9 | B11: Pooja Mehta | C11: 70 | D11: 81 | E11: 82 | F11: 79 | G11: 92 | H11: 80 | I11: 76 | J11: 85 | K11: 76 | L11: 83 | M11: 86 | N11: 77 | O11: =SUM(Table6[[#This Row],[Math]:[Physics]]) -> 967 | P11: =SUM(C11:N11)/1200 -> 0.80583333
A12: 10 | B12: Arjun Verma | C12: 73 | D12: 70 | E12: 83 | F12: 76 | G12: 95 | H12: 81 | I12: 73 | J12: 86 | K12: 76 | L12: 84 | M12: 95 | N12: 87 | O12: =SUM(Table6[[#This Row],[Math]:[Physics]]) -> 979 | P12: =SUM(C12:N12)/1200 -> 0.81583333
A13: 11 | B13: Sneha Jain | C13: 84 | D13: 71 | E13: 66 | F13: 80 | G13: 81 | H13: 71 | I13: 90 | J13: 82 | K13: 73 | L13: 71 | M13: 93 | N13: 76 | O13: =SUM(Table6[[#This Row],[Math]:[Physics]]) -> 938 | P13: =SUM(C13:N13)/1200 -> 0.78166667
A14: 12 | B14: Karan Yadav | C14: 80 | D14: 84 | E14: 89 | F14: 74 | G14: 89 | H14: 94 | I14: 73 | J14: 83 | K14: 65 | L14: 94 | M14: 71 | N14: 86 | O14: =SUM(Table6[[#This Row],[Math]:[Physics]]) -> 982 | P14: =SUM(C14:N14)/1200 -> 0.81833333
... A32: 30 | B32: Manish Singh | C32: 76 | D32: 95 | E32: 91 | F32: 68 | G32: 73 | H32: 94 | I32: 79 | J32: 90 | K32: 94 | L32: 72 | M32: 93 | N32: 72 | O32: =SUM(Table6[[#This Row],[Math]:[Physics]]) -> 997 | P32: =SUM(C32:N32)/1200 -> 0.83083333

Sheet Class 9
A1: 🎓 Class 9th Students
A2: Student ID | B2: Name | C2: Math | D2: Science | E2: History | F2: English | G2: Business Studies | H2: Economics | I2: Geography | J2: Music | K2: Computer Science | L2: Art | M2: Chemistry | N2: Physics | O2: Total | P2: Percentage
A3: 1 | B3: Aarav Sharma | C3: 83 | D3: 78 | E3: 78 | F3: 79 | G3: 67 | H3: 74 | I3: 66 | J3: 86 | K3: 72 | L3: 94 | M3: 92 | N3: 94 | O3: =SUM(Table7[[#This Row],[Math]:[Physics]]) -> 963 | P3: =SUM(C3:N3)/1200 -> 0.8025
A4: 2 | B4: Vihaan Singh | C4: 92 | D4: 66 | E4: 81 | F4: 69 | G4: 75 | H4: 80 | I4: 75 | J4: 67 | K4: 84 | L4: 88 | M4: 95 | N4: 91 | O4: =SUM(Table7[[#This Row],[Math]:[Physics]]) -> 963 | P4: =SUM(C4:N4)/1200 -> 0.8025
A5: 3 | B5: Ananya Kumar | C5: 68 | D5: 70 | E5: 91 | F5: 84 | G5: 77 | H5: 70 | I5: 72 | J5: 92 | K5: 65 | L5: 80 | M5: 82 | N5: 81 | O5: =SUM(Table7[[#This Row],[Math]:[Physics]]) -> 932 | P5: =SUM(C5:N5)/1200 -> 0.77666667
A6: 4 | B6: Ishaan Verma | C6: 76 | D6: 78 | E6: 87 | F6: 66 | G6: 87 | H6: 71 | I6: 70 | J6: 66 | K6: 71 | L6: 90 | M6: 71 | N6: 85 | O6: =SUM(Table7[[#This Row],[Math]:[Physics]]) -> 918 | P6: =SUM(C6:N6)/1200 -> 0.765
A7: 5 | B7: Diya Sharma | C7: 86 | D7: 82 | E7: 69 | F7: 69 | G7: 66 | H7: 82 | I7: 90 | J7: 65 | K7: 88 | L7: 74 | M7: 84 | N7: 90 | O7: =SUM(Table7[[#This Row],[Math]:[Physics]]) -> 945 | P7: =SUM(C7:N7)/1200 -> 0.7875
A8: 6 | B8: Aditya Yadav | C8: 91 | D8: 74 | E8: 80 | F8: 78 | G8: 89 | H8: 93 | I8: 65 | J8: 74 | K8: 81 | L8: 92 | M8: 73 | N8: 93 | O8: =SUM(Table7[[#This Row],[Math]:[Physics]]) -> 983 | P8: =SUM(C8:N8)/1200 -> 0.81916667
A9: 7 | B9: Kavya Mehta | C9: 89 | D9: 73 | E9: 69 | F9: 71 | G9: 72 | H9: 73 | I9: 84 | J9: 81 | K9: 94 | L9: 82 | M9: 69 | N9: 74 | O9: =SUM(Table7[[#This Row],[Math]:[Physics]]) -> 931 | P9: =SUM(C9:N9)/1200 -> 0.77583333
A10: 8 | B10: Rohan Yadav | C10: 94 | D10: 72 | E10: 94 | F10: 88 | G10: 88 | H10: 87 | I10: 88 | J10: 90 | K10: 83 | L10: 79 | M10: 66 | N10: 70 | O10: =SUM(Table7[[#This Row],[Math]:[Physics]]) -> 999 | P10: =SUM(C10:N10)/1200 -> 0.8325
A11: 9 | B11: Pooja Jain | C11: 82 | D11: 83 | E11: 71 | F11: 85 | G11: 80 | H11: 78 | I11: 88 | J11: 71 | K11: 66 | L11: 83 | M11: 90 | N11: 78 | O11: =SUM(Table7[[#This Row],[Math]:[Physics]]) -> 955 | P11: =SUM(C11:N11)/1200 -> 0.79583333
A12: 10 | B12: Arjun Sharma | C12: 72 | D12: 75 | E12: 80 | F12: 71 | G12: 84 | H12: 86 | I12: 90 | J12: 95 | K12: 83 | L12: 75 | M12: 81 | N12: 84 | O12: =SUM(Table7[[#This Row],[Math]:[Physics]]) -> 976 | P12: =SUM(C12:N12)/1200 -> 0.81333333
A13: 11 | B13: Sneha Kumar | C13: 91 | D13: 82 | E13: 75 | F13: 85 | G13: 92 | H13: 76 | I13: 69 | J13: 67 | K13: 71 | L13: 84 | M13: 83 | N13: 73 | O13: =SUM(Table7[[#This Row],[Math]:[Physics]]) -> 948 | P13: =SUM(C13:N13)/1200 -> 0.79
A14: 12 | B14: Karan Sharma | C14: 95 | D14: 73 | E14: 81 | F14: 79 | G14: 67 | H14: 69 | I14: 77 | J14: 79 | K14: 88 | L14: 88 | M14: 72 | N14: 92 | O14: =SUM(Table7[[#This Row],[Math]:[Physics]]) -> 960 | P14: =SUM(C14:N14)/1200 -> 0.8
... A32: 30 | B32: Manish Yadav | C32: 76 | D32: 94 | E32: 76 | F32: 73 | G32: 91 | H32: 78 | I32: 75 | J32: 80 | K32: 77 | L32: 94 | M32: 87 | N32: 71 | O32: =SUM(Table7[[#This Row],[Math]:[Physics]]) -> 972 | P32: =SUM(C32:N32)/1200 -> 0.81

Sheet Class 10
A1: 🎓 Class 10th Students | G1: 🎓 Class 6 Students
A2: Student ID | B2: Name | C2: Math | D2: Science | E2: History | F2: English | G2: Business Studies | H2: Economics | I2: Geography | J2: Music | K2: Computer Science | L2: Art | M2: Chemistry | N2: Physics | O2: Total | P2: Percentage
A3: 1 | B3: Aarav Yadav | C3: 65 | D3: 84 | E3: 71 | F3: 88 | G3: 71 | H3: 92 | I3: 92 | J3: 75 | K3: 85 | L3: 71 | M3: 94 | N3: 67 | O3: =SUM(Table8[[#This Row],[Math]:[Physics]]) -> 955 | P3: =SUM(C3:N3)/1200 -> 0.79583333
A4: 2 | B4: Vihaan Mehta | C4: 88 | D4: 95 | E4: 76 | F4: 82 | G4: 67 | H4: 84 | I4: 70 | J4: 88 | K4: 82 | L4: 78 | M4: 77 | N4: 91 | O4: =SUM(Table8[[#This Row],[Math]:[Physics]]) -> 978 | P4: =SUM(C4:N4)/1200 -> 0.815
A5: 3 | B5: Ananya Patel | C5: 86 | D5: 68 | E5: 89 | F5: 78 | G5: 66 | H5: 84 | I5: 79 | J5: 88 | K5: 79 | L5: 68 | M5: 88 | N5: 71 | O5: =SUM(Table8[[#This Row],[Math]:[Physics]]) -> 944 | P5: =SUM(C5:N5)/1200 -> 0.78666667
A6: 4 | B6: Ishaan Patel | C6: 79 | D6: 75 | E6: 93 | F6: 79 | G6: 77 | H6: 89 | I6: 76 | J6: 94 | K6: 84 | L6: 77 | M6: 73 | N6: 65 | O6: =SUM(Table8[[#This Row],[Math]:[Physics]]) -> 961 | P6: =SUM(C6:N6)/1200 -> 0.80083333
A7: 5 | B7: Diya Singh | C7: 93 | D7: 84 | E7: 74 | F7: 86 | G7: 70 | H7: 70 | I7: 72 | J7: 95 | K7: 65 | L7: 68 | M7: 69 | N7: 71 | O7: =SUM(Table8[[#This Row],[Math]:[Physics]]) -> 917 | P7: =SUM(C7:N7)/1200 -> 0.76416667
A8: 6 | B8: Aditya Yadav | C8: 70 | D8: 95 | E8: 88 | F8: 88 | G8: 84 | H8: 87 | I8: 79 | J8: 91 | K8: 70 | L8: 80 | M8: 78 | N8: 93 | O8: =SUM(Table8[[#This Row],[Math]:[Physics]]) -> 1003 | P8: =SUM(C8:N8)/1200 -> 0.83583333
A9: 7 | B9: Kavya Sharma | C9: 70 | D9: 87 | E9: 77 | F9: 90 | G9: 67 | H9: 88 | I9: 92 | J9: 80 | K9: 75 | L9: 81 | M9: 91 | N9: 86 | O9: =SUM(Table8[[#This Row],[Math]:[Physics]]) -> 984 | P9: =SUM(C9:N9)/1200 -> 0.82
A10: 8 | B10: Rohan Mehta | C10: 76 | D10: 67 | E10: 91 | F10: 72 | G10: 89 | H10: 67 | I10: 65 | J10: 81 | K10: 91 | L10: 85 | M10: 95 | N10: 84 | O10: =SUM(Table8[[#This Row],[Math]:[Physics]]) -> 963 | P10: =SUM(C10:N10)/1200 -> 0.8025
A11: 9 | B11: Pooja Yadav | C11: 68 | D11: 75 | E11: 79 | F11: 93 | G11: 94 | H11: 94 | I11: 73 | J11: 74 | K11: 93 | L11: 68 | M11: 92 | N11: 94 | O11: =SUM(Table8[[#This Row],[Math]:[Physics]]) -> 997 | P11: =SUM(C11:N11)/1200 -> 0.83083333
A12: 10 | B12: Arjun Sharma | C12: 94 | D12: 67 | E12: 83 | F12: 88 | G12: 73 | H12: 69 | I12: 95 | J12: 94 | K12: 90 | L12: 78 | M12: 77 | N12: 82 | O12: =SUM(Table8[[#This Row],[Math]:[Physics]]) -> 990 | P12: =SUM(C12:N12)/1200 -> 0.825
A13: 11 | B13: Sneha Verma | C13: 88 | D13: 68 | E13: 75 | F13: 88 | G13: 79 | H13: 74 | I13: 83 | J13: 89 | K13: 79 | L13: 80 | M13: 87 | N13: 95 | O13: =SUM(Table8[[#This Row],[Math]:[Physics]]) -> 985 | P13: =SUM(C13:N13)/1200 -> 0.82083333
A14: 12 | B14: Karan Gupta | C14: 71 | D14: 72 | E14: 76 | F14: 87 | G14: 83 | H14: 95 | I14: 68 | J14: 79 | K14: 95 | L14: 77 | M14: 85 | N14: 86 | O14: =SUM(Table8[[#This Row],[Math]:[Physics]]) -> 974 | P14: =SUM(C14:N14)/1200 -> 0.81166667
... A32: 30 | B32: Manish Sharma | C32: 70 | D32: 77 | E32: 75 | F32: 83 | G32: 71 | H32: 85 | I32: 75 | J32: 91 | K32: 74 | L32: 71 | M32: 73 | N32: 75 | O32: =SUM(Table8[[#This Row],[Math]:[Physics]]) -> 920 | P32: =SUM(C32:N32)/1200 -> 0.76666667

Sheet Events
A1: 📅 Event Status Tracker
A2: Course ID | B2: Course Name | C2: Year | D2: Semester | E2: Activities | F2: Due Date | G2: Month | H2: Status
A3: WR121 | B3: Writing Composition | C3: 2025 | D3: Spring | E3: Quiz #1 | F3: 45672 | G3: =TEXT(Table2[[#This Row],[Due Date]],"MMM") -> Jan | H3: Completed
A4: CS120 | B4: Intro to Computer | C4: 2025 | D4: Spring | E4: Assignment #1 | F4: 45682 | G4: =TEXT(Table2[[#This Row],[Due Date]],"MMM") -> Jan | H4: Completed
A5: MTH101 | B5: Mathematics | C5: 2025 | D5: Spring | E5: Class Test | F5: 45703 | G5: =TEXT(Table2[[#This Row],[Due Date]],"MMM") -> Feb | H5: Completed
A6: SCI201 | B6: Science | C6: 2025 | D6: Spring | E6: Lab Practical | F6: 45721 | G6: =TEXT(Table2[[#This Row],[Due Date]],"MMM") -> Mar | H6: Completed
A7: ENG101 | B7: English | C7: 2025 | D7: Spring | E7: Essay Submission | F7: 45726 | G7: =TEXT(Table2[[#This Row],[Due Date]],"MMM") -> Mar | H7: Completed
A8: BUS301 | B8: Business Studies | C8: 2025 | D8: Spring | E8: Project Work | F8: 45721 | G8: =TEXT(Table2[[#This Row],[Due Date]],"MMM") -> Mar | H8: Completed
A9: ECO101 | B9: Economics | C9: 2025 | D9: Spring | E9: Case Study | F9: 45757 | G9: =TEXT(Table2[[#This Row],[Due Date]],"MMM") -> Apr | H9: Completed
A10: GEO201 | B10: Geography | C10: 2025 | D10: Spring | E10: Map Work | F10: 45769 | G10: =TEXT(Table2[[#This Row],[Due Date]],"MMM") -> Apr | H10: Completed
A11: MUS101 | B11: Music | C11: 2025 | D11: Spring | E11: Performance | F11: 45836 | G11: =TEXT(Table2[[#This Row],[Due Date]],"MMM") -> Jun | H11: Completed
A12: ART101 | B12: Art | C12: 2025 | D12: Spring | E12: Drawing Submission | F12: 45797 | G12: =TEXT(Table2[[#This Row],[Due Date]],"MMM") -> May | H12: Completed
A13: CSC101 | B13: Computer Science | C13: 2025 | D13: Spring | E13: Practical Exam | F13: 45818 | G13: =TEXT(Table2[[#This Row],[Due Date]],"MMM") -> Jun | H13: Completed
A14: CHE101 | B14: Chemistry | C14: 2025 | D14: Spring | E14: Lab Test | F14: 45833 | G14: =TEXT(Table2[[#This Row],[Due Date]],"MMM") -> Jun | H14: Completed
... A22: ECO101 | B22: Economics | C22: 2025 | D22: Spring | E22: Final Exam | F22: 46016 | G22: =TEXT(Table2[[#This Row],[Due Date]],"MMM") -> Dec | H22: Pending

Sheet Pivot Table
A2: 📊 Completed vs Pending Activities
A3: Count of Activities | B3: Column Labels
A4: Months | B4: Completed | C4: Pending
A5: Jan | B5: 2
A6: Feb | B6: 1
A7: Mar | B7: 3
A8: Apr | B8: 2
A9: May | B9: 1
A10: Jun | B10: 3
A11: Aug | C11: 4
A12: Sep | C12: 2
A13: Nov | C13: 1
A14: Dec | C14: 1
A15: Grand Total | B15: 12 | C15: 8

Sheet Exam timetable
B2: " Examination Time Table 2025"
B3: Subject | C3: Date | D3: Day | E3: Time
B4: Math | C4: 45748 | D4: Monday | E4: 0.41666667
B5: Science | C5: 45749 | D5: Tuesday | E5: 0.41666667
B6: History | C6: 45750 | D6: Wednesday | E6: 0.41666667
B7: English | C7: 45751 | D7: Thursday | E7: 0.41666667
B8: Business Studies | C8: 45752 | D8: Friday | E8: 0.41666667
B9: Economics | C9: 45754 | D9: Monday | E9: 0.41666667
B10: Geography | C10: 45755 | D10: Tuesday | E10: 0.41666667
B11: Music | C11: 45756 | D11: Wednesday | E11: 0.41666667
B12: Computer Science | C12: 45757 | D12: Thursday | E12: 0.41666667
B13: Art | C13: 45758 | D13: Friday | E13: 0.41666667
B14: Chemistry | C14: 45759 | D14: Saturday | E14: 0.41666667
B15: Physics | C15: 45761 | D15: Monday | E15: 0.41666667

Sheet All Students
A1: All Students Performance Data | F1: Top 3 Students of the School 🏆 | K1: 🎯 Class-wise Toppers
A2: Class | B2: Name | C2: Percentage | D2: Display | F2: Class | G2: Name | H2: Percentage | I2: Display | K2: Class | L2: Topper Name | M2: Percentage | N2: Display
A3: 6 | B3: ='Class 6'!B26 -> Jivani Patel | C3: ='Class 6'!P26 -> 0.87333333 | D3: =B3 & " | Class " & A3 & " | " & ROUND(C3*100,0) & "%" -> Jivani Patel | Class 6 | 87% | F3: 6 | G3: Jivani Patel | H3: 0.87333333 | I3: Jivani Patel Class 6 87% | K3: 6 | L3: {=INDEX(B:B, MATCH(1, (A:A=K3)*(C:C=M3), 0))} -> Jivani Patel | M3: =_xlfn.MAXIFS(C:C, A:A, K3) -> 0.87333333 | N3: =L3 & " | Class " & K3 & " | " & ROUND(M3*100,0) & "%" -> Jivani Patel | Class 6 | 87%
A4: 6 | B4: ='Class 6'!B17 -> Tanya Jain | C4: ='Class 6'!P17 -> 0.84166667 | D4: =B4 & " | Class " & A4 & " | " & ROUND(C4*100,0) & "%" -> Tanya Jain | Class 6 | 84% | F4: 10 | G4: Harsh Jain | H4: 0.8725 | I4: Harsh Jain Class 10 87% | K4: 7 | L4: {=INDEX(B:B, MATCH(1, (A:A=K4)*(C:C=M4), 0))} -> Ravi Gupta | M4: =_xlfn.MAXIFS(C:C, A:A, K4) -> 0.85166667 | N4: =L4 & " | Class " & K4 & " | " & ROUND(M4*100,0) & "%" -> Ravi Gupta | Class 7 | 85%
A5: 6 | B5: ='Class 6'!B21 -> Ritu Kumar | C5: ='Class 6'!P21 -> 0.83916667 | D5: =B5 & " | Class " & A5 & " | " & ROUND(C5*100,0) & "%" -> Ritu Kumar | Class 6 | 84% | F5: 7 | G5: Ravi Gupta | H5: 0.85166667 | I5: Ravi Gupta Class 7 85% | K5: 8 | L5: {=INDEX(B:B, MATCH(1, (A:A=K5)*(C:C=M5), 0))} -> Nikhil Kumar | M5: =_xlfn.MAXIFS(C:C, A:A, K5) -> 0.84833333 | N5: =L5 & " | Class " & K5 & " | " & ROUND(M5*100,0) & "%" -> Nikhil Kumar | Class 8 | 85%
A6: 6 | B6: ='Class 6'!B15 -> Meera Joshi | C6: ='Class 6'!P15 -> 0.82666667 | D6: =B6 & " | Class " & A6 & " | " & ROUND(C6*100,0) & "%" -> Meera Joshi | Class 6 | 83% | K6: 9 | L6: {=INDEX(B:B, MATCH(1, (A:A=K6)*(C:C=M6), 0))} -> Rohan Yadav | M6: =_xlfn.MAXIFS(C:C, A:A, K6) -> 0.8325 | N6: =L6 & " | Class " & K6 & " | " & ROUND(M6*100,0) & "%" -> Rohan Yadav | Class 9 | 83%
A7: 6 | B7: ='Class 6'!B31 -> Shreya Sharma | C7: ='Class 6'!P31 -> 0.82666667 | D7: =B7 & " | Class " & A7 & " | " & ROUND(C7*100,0) & "%" -> Shreya Sharma | Class 6 | 83% | K7: 10 | L7: {=INDEX(B:B, MATCH(1, (A:A=K7)*(C:C=M7), 0))} -> Harsh Jain | M7: =_xlfn.MAXIFS(C:C, A:A, K7) -> 0.8725 | N7: =L7 & " | Class " & K7 & " | " & ROUND(M7*100,0) & "%" -> Harsh Jain | Class 10 | 87%
A8: 6 | B8: ='Class 6'!B27 -> Neha Patel | C8: ='Class 6'!P27 -> 0.825 | D8: =B8 & " | Class " & A8 & " | " & ROUND(C8*100,0) & "%" -> Neha Patel | Class 6 | 83%
A9: 6 | B9: ='Class 6'!B11 -> Pooja Patel | C9: ='Class 6'!P11 -> 0.82166667 | D9: =B9 & " | Class " & A9 & " | " & ROUND(C9*100,0) & "%" -> Pooja Patel | Class 6 | 82%
A10: 6 | B10: ='Class 6'!B32 -> Manish Gupta | C10: ='Class 6'!P32 -> 0.81916667 | D10: =B10 & " | Class " & A10 & " | " & ROUND(C10*100,0) & "%" -> Manish Gupta | Class 6 | 82%
A11: 6 | B11: ='Class 6'!B13 -> Sneha Joshi | C11: ='Class 6'!P13 -> 0.8175 | D11: =B11 & " | Class " & A11 & " | " & ROUND(C11*100,0) & "%" -> Sneha Joshi | Class 6 | 82%
A12: 6 | B12: ='Class 6'!B4 -> Vihaan Verma | C12: ='Class 6'!P4 -> 0.81333333 | D12: =B12 & " | Class " & A12 & " | " & ROUND(C12*100,0) & "%" -> Vihaan Verma | Class 6 | 81%
A13: 6 | B13: ='Class 6'!B14 -> Karan Gupta | C13: ='Class 6'!P14 -> 0.8075 | D13: =B13 & " | Class " & A13 & " | " & ROUND(C13*100,0) & "%" -> Karan Gupta | Class 6 | 81%
A14: 6 | B14: ='Class 6'!B22 -> Yash Mehta | C14: ='Class 6'!P22 -> 0.8075 | D14: =B14 & " | Class " & A14 & " | " & ROUND(C14*100,0) & "%" -> Yash Mehta | Class 6 | 81%
A15: 6 | B15: ='Class 6'!B29 -> Sakshi Sharma | C15: ='Class 6'!P29 -> 0.80416667 | D15: =B15 & " | Class " & A15 & " | " & ROUND(C15*100,0) & "%" -> Sakshi Sharma | Class 6 | 80%
A16: 6 | B16: ='Class 6'!B23 -> Priyanka Sharma | C16: ='Class 6'!P23 -> 0.80333333 | D16: =B16 & " | Class " & A16 & " | " & ROUND(C16*100,0) & "%" -> Priyanka Sharma | Class 6 | 80%
A17: 6 | B17: ='Class 6'!B3 -> Aarav Kumar | C17: ='Class 6'!P3 -> 0.80166667 | D17: =B17 & " | Class " & A17 & " | " & ROUND(C17*100,0) & "%" -> Aarav Kumar | Class 6 | 80%
A18: 6 | B18: ='Class 6'!B12 -> Arjun Verma | C18: ='Class 6'!P12 -> 0.8 | D18: =B18 & " | Class " & A18 & " | " & ROUND(C18*100,0) & "%" -> Arjun Verma | Class 6 | 80%
A19: 6 | B19: ='Class 6'!B25 -> Simran Singh | C19: ='Class 6'!P25 -> 0.79583333 | D19: =B19 & " | Class " & A19 & " | " & ROUND(C19*100,0) & "%" -> Simran Singh | Class 6 | 80%
A20: 6 | B20: ='Class 6'!B5 -> Ananya Mehta | C20: ='Class 6'!P5 -> 0.795 | D20: =B20 & " | Class " & A20 & " | " & ROUND(C20*100,0) & "%" -> Ananya Mehta | Class 6 | 80%
A21: 6 | B21: ='Class 6'!B18 -> Aman Jain | C21: ='Class 6'!P18 -> 0.7875 | D21: =B21 & " | Class " & A21 & " | " & ROUND(C21*100,0) & "%" -> Aman Jain | Class 6 | 79%
A22: 6 | B22: ='Class 6'!B20 -> Nikhil Mehta | C22: ='Class 6'!P20 -> 0.78666667 | D22: =B22 & " | Class " & A22 & " | " & ROUND(C22*100,0) & "%" -> Nikhil Mehta | Class 6 | 79%
A23: 6 | B23: ='Class 6'!B6 -> Ishaan Gupta | C23: ='Class 6'!P6 -> 0.785 | D23: =B23 & " | Class " & A23 & " | " & ROUND(C23*100,0) & "%" -> Ishaan Gupta | Class 6 | 79%
A24: 6 | B24: ='Class 6'!B8 -> Aditya Patel | C24: ='Class 6'!P8 -> 0.78416667 | D24: =B24 & " | Class " & A24 & " | " & ROUND(C24*100,0) & "%" -> Aditya Patel | Class 6 | 78%
A25: 6 | B25: ='Class 6'!B28 -> Harsh Singh | C25: ='Class 6'!P28 -> 0.7825 | D25: =B25 & " | Class " & A25 & " | " & ROUND(C25*100,0) & "%" -> Harsh Singh | Class 6 | 78%
A26: 6 | B26: ='Class 6'!B10 -> Rohan Joshi | C26: ='Class 6'!P10 -> 0.7775 | D26: =B26 & " | Class " & A26 & " | " & ROUND(C26*100,0) & "%" -> Rohan Joshi | Class 6 | 78%
A27: 6 | B27: ='Class 6'!B30 -> Rajesh Joshi | C27: ='Class 6'!P30 -> 0.77666667 | D27: =B27 & " | Class " & A27 & " | " & ROUND(C27*100,0) & "%" -> Rajesh Joshi | Class 6 | 78%
A28: 6 | B28: ='Class 6'!B16 -> Rahul Kumar | C28: ='Class 6'!P16 -> 0.7725 | D28: =B28 & " | Class " & A28 & " | " & ROUND(C28*100,0) & "%" -> Rahul Kumar | Class 6 | 77%
A29: 6 | B29: ='Class 6'!B7 -> Diya Yadav | C29: ='Class 6'!P7 -> 0.77166667 | D29: =B29 & " | Class " & A29 & " | " & ROUND(C29*100,0) & "%" -> Diya Yadav | Class 6 | 77%
A30: 6 | B30: ='Class 6'!B24 -> Deepak Patel | C30: ='Class 6'!P24 -> 0.77083333 | D30: =B30 & " | Class " & A30 & " | " & ROUND(C30*100,0) & "%" -> Deepak Patel | Class 6 | 77%
A31: 6 | B31: ='Class 6'!B19 -> Isha Mehta | C31: ='Class 6'!P19 -> 0.76416667 | D31: =B31 & " | Class " & A31 & " | " & ROUND(C31*100,0) & "%" -> Isha Mehta | Class 6 | 76%
A32: 6 | B32: ='Class 6'!B9 -> Kavya Singh | C32: ='Class 6'!P9 -> 0.7525 | D32: =B32 & " | Class " & A32 & " | " & ROUND(C32*100,0) & "%" -> Kavya Singh | Class 6 | 75%
A33: 7 | B33: ='Class 7'!B11 -> Ravi Gupta | C33: ='Class 7'!P11 -> 0.85166667 | D33: =B33 & " | Class " & A33 & " | " & ROUND(C33*100,0) & "%" -> Ravi Gupta | Class 7 | 85%
A34: 7 | B34: ='Class 7'!B8 -> Aditya Kumar | C34: ='Class 7'!P8 -> 0.84416667 | D34: =B34 & " | Class " & A34 & " | " & ROUND(C34*100,0) & "%" -> Aditya Kumar | Class 7 | 84%
A35: 7 | B35: ='Class 7'!B6 -> Ishaan Kumar | C35: ='Class 7'!P6 -> 0.83166667 | D35: =B35 & " | Class " & A35 & " | " & ROUND(C35*100,0) & "%" -> Ishaan Kumar | Class 7 | 83%
A36: 7 | B36: ='Class 7'!B19 -> Isha Gupta | C36: ='Class 7'!P19 -> 0.825 | D36: =B36 & " | Class " & A36 & " | " & ROUND(C36*100,0) & "%" -> Isha Gupta | Class 7 | 83%
A37: 7 | B37: ='Class 7'!B14 -> Karan Yadav | C37: ='Class 7'!P14 -> 0.82 | D37: =B37 & " | Class " & A37 & " | " & ROUND(C37*100,0) & "%" -> Karan Yadav | Class 7 | 82%
A38: 7 | B38: ='Class 7'!B21 -> Ritu Joshi | C38: ='Class 7'!P21 -> 0.81416667 | D38: =B38 & " | Class " & A38 & " | " & ROUND(C38*100,0) & "%" -> Ritu Joshi | Class 7 | 81%
A39: 7 | B39: ='Class 7'!B29 -> Sakshi Sharma | C39: ='Class 7'!P29 -> 0.81416667 | D39: =B39 & " | Class " & A39 & " | " & ROUND(C39*100,0) & "%" -> Sakshi Sharma | Class 7 | 81%
A40: 7 | B40: ='Class 7'!B30 -> Rajesh Sharma | C40: ='Class 7'!P30 -> 0.81333333 | D40: =B40 & " | Class " & A40 & " | " & ROUND(C40*100,0) & "%" -> Rajesh Sharma | Class 7 | 81%
...
